Workbook

Sheet Objednávka
A1: PDM 8CH rev 0.1 – objednávka součástek
A2: Žlutá pole jsou vstupy: počet desek, rezerva a ceny. Množství a součty se přepočítají samy.
A3: Počet desek | C3: 2
A4: Rezerva pasivních součástek | C4: 0.1 | D4: Pasivní součástky se objednávají s rezervou, polovodiče a konektory přesně.
A5: Min. kusů navíc u pasivních (ztráty při osazování) | C5: 5
A7: Poz. | B7: Označení na desce | C7: Ks / deska | D7: Ks objednat | E7: Hodnota | F7: Pouzdro | G7: Výrobce | H7: MPN (objednací číslo) | I7: Popis | J7: Typ | K7: Osadit | L7: Cena / ks (Kč) | M7: Cena celkem (Kč) | N7: Poznámka
A8: 1 | B8: D13, D17, D21, D25, D29, D33, D37, D41 | C8: 8 | D8: =IF(K8="NE",0,IF(J8="Pasivní",ROUNDUP(C8*$C$3*(1+$C$4),0)+$C$5,C8*$C$3)) -> 16 | E8: GREEN | F8: LED_0805 | G8: Wurth Elektronik | H8: 150080GS75000 | I8: LED zelena 0805 | J8: Polovodič | K8: ANO | M8: =IF(L8="","",D8*L8)
A9: 2 | B9: D14, D18, D22, D26, D30, D34, D38, D42 | C9: 8 | D9: =IF(K9="NE",0,IF(J9="Pasivní",ROUNDUP(C9*$C$3*(1+$C$4),0)+$C$5,C9*$C$3)) -> 16 | E9: RED | F9: LED_0805 | G9: Wurth Elektronik | H9: 150080RS75000 | I9: LED cervena 0805 | J9: Polovodič | K9: ANO | M9: =IF(L9="","",D9*L9)
A10: 3 | B10: U3, U4 | C10: 2 | D10: =IF(K10="NE",0,IF(J10="Pasivní",ROUNDUP(C10*$C$3*(1+$C$4),0)+$C$5,C10*$C$3)) -> 4 | E10: 74HC86-Q100 | F10: SOIC-14_3.9x8.7mm_P1.27mm | G10: Nexperia | H10: 74HC86D-Q100J | I10: 4x XOR, AEC-Q100 | J10: Polovodič | K10: ANO | M10: =IF(L10="","",D10*L10)
A11: 4 | B11: D9, D10, D11, D12, D15, D16, D19, D20, D23, D24, D27, D28, D31, D32, D35, D36, D39, D40, D43, D44 | C11: 20 | D11: =IF(K11="NE",0,IF(J11="Pasivní",ROUNDUP(C11*$C$3*(1+$C$4),0)+$C$5,C11*$C$3)) -> 40 | E11: BAT54 | F11: SOT-23 | G11: Nexperia | H11: BAT54,215 | I11: Schottky 30V 200mA SOT-23 | J11: Polovodič | K11: ANO | M11: =IF(L11="","",D11*L11)
A12: 5 | B12: D4, D5, D6, D7, D8 | C12: 5 | D12: =IF(K12="NE",0,IF(J12="Pasivní",ROUNDUP(C12*$C$3*(1+$C$4),0)+$C$5,C12*$C$3)) -> 10 | E12: BAV99 | F12: SOT-23 | G12: Nexperia | H12: BAV99,215 | I12: Dvojita dioda 100V SOT-23 | J12: Polovodič | K12: ANO | M12: =IF(L12="","",D12*L12)
A13: 6 | B13: Q2 | C13: 1 | D13: =IF(K13="NE",0,IF(J13="Pasivní",ROUNDUP(C13*$C$3*(1+$C$4),0)+$C$5,C13*$C$3)) -> 2 | E13: BSP75N | F13: SOT-223-3_TabPin2 | G13: Infineon | H13: BSP75NH6327XTSA1 | I13: Chraneny low-side spinac 60V (kontrolka) | J13: Polovodič | K13: ANO | M13: =IF(L13="","",D13*L13)
A14: 7 | B14: Q1 | C14: 1 | D14: =IF(K14="NE",0,IF(J14="Pasivní",ROUNDUP(C14*$C$3*(1+$C$4),0)+$C$5,C14*$C$3)) -> 2 | E14: BSS84 | F14: SOT-23 | G14: Nexperia | H14: BSS84,215 | I14: P-MOSFET 50V SOT-23 | J14: Polovodič | K14: ANO | M14: =IF(L14="","",D14*L14)
A15: 8 | B15: U10, U11, U12, U13, U14, U15, U16, U17 | C15: 8 | D15: =IF(K15="NE",0,IF(J15="Pasivní",ROUNDUP(C15*$C$3*(1+$C$4),0)+$C$5,C15*$C$3)) -> 16 | E15: BTS7002-1EPP | F15: Infineon_PG-TSDSO-14-22 | G15: Infineon | H15: BTS70021EPPXUMA1 | I15: PROFET+2 high-side spinac 2,6 mOhm | J15: Polovodič | K15: ANO | M15: =IF(L15="","",D15*L15) | N15: Pod pouzdrem tepelné prokovy; měď 2 oz
A16: 9 | B16: U5, U6, U7, U8, U9 | C16: 5 | D16: =IF(K16="NE",0,IF(J16="Pasivní",ROUNDUP(C16*$C$3*(1+$C$4),0)+$C$5,C16*$C$3)) -> 10 | E16: LM2901AVQDR (-Q1) | F16: SOIC-14_3.9x8.7mm_P1.27mm | G16: Texas Instruments | H16: LM2901AVQDRQ1 | I16: Ctyrnasobny komparator, AEC-Q100 | J16: Polovodič | K16: ANO | M16: =IF(L16="","",D16*L16) | N16: U9 je stejný typ (oscilátor a test kontrolky)
A17: 10 | B17: U1 | C17: 1 | D17: =IF(K17="NE",0,IF(J17="Pasivní",ROUNDUP(C17*$C$3*(1+$C$4),0)+$C$5,C17*$C$3)) -> 2 | E17: LM2937IMP-5.0 | F17: SOT-223-3_TabPin2 | G17: Texas Instruments | H17: LM2937IMP-5.0/NOPB | I17: LDO 5V 500mA SOT-223 | J17: Polovodič | K17: ANO | M17: =IF(L17="","",D17*L17)
A18: 11 | B18: D45 | C18: 1 | D18: =IF(K18="NE",0,IF(J18="Pasivní",ROUNDUP(C18*$C$3*(1+$C$4),0)+$C$5,C18*$C$3)) -> 2 | E18: 18V 1W SMAZ18 | F18: D_SMA | G18: Diodes Inc. | H18: SMAZ18-13-F | I18: Zenerova dioda 18V 1W SMA | J18: Polovodič | K18: ANO | M18: =IF(L18="","",D18*L18)
A19: 12 | B19: D3 | C19: 1 | D19: =IF(K19="NE",0,IF(J19="Pasivní",ROUNDUP(C19*$C$3*(1+$C$4),0)+$C$5,C19*$C$3)) -> 2 | E19: SMBJ33A | F19: D_SMB | G19: Littelfuse | H19: SMBJ33A | I19: TVS 33V 600W SMB | J19: Polovodič | K19: ANO | M19: =IF(L19="","",D19*L19)
A20: 13 | B20: D1 | C20: 1 | D20: =IF(K20="NE",0,IF(J20="Pasivní",ROUNDUP(C20*$C$3*(1+$C$4),0)+$C$5,C20*$C$3)) -> 2 | E20: SMCJ33A | F20: D_SMC | G20: Littelfuse | H20: SMCJ33A | I20: TVS 33V 1500W SMC | J20: Polovodič | K20: ANO | M20: =IF(L20="","",D20*L20)
A21: 14 | B21: D2 | C21: 1 | D21: =IF(K21="NE",0,IF(J21="Pasivní",ROUNDUP(C21*$C$3*(1+$C$4),0)+$C$5,C21*$C$3)) -> 2 | E21: SS34 | F21: D_SMA | G21: Vishay | H21: SS34-E3/61T | I21: Schottky 40V 3A SMA | J21: Polovodič | K21: ANO | M21: =IF(L21="","",D21*L21)
A22: 15 | B22: F1 | C22: 1 | D22: =IF(K22="NE",0,IF(J22="Pasivní",ROUNDUP(C22*$C$3*(1+$C$4),0)+$C$5,C22*$C$3)) -> 2 | E22: 0.5A PTC 1812L050/33 | F22: Fuse_1812 | G22: Littelfuse | H22: 1812L050/33MR | I22: Vratna pojistka PTC 0,5A hold 33V 1812 | J22: Konektor/ostatní | K22: ANO | M22: =IF(L22="","",D22*L22)
A23: 16 | B23: JP1, JP2, JP3 | C23: 3 | D23: =IF(K23="NE",0,IF(J23="Pasivní",ROUNDUP(C23*$C$3*(1+$C$4),0)+$C$5,C23*$C$3)) -> 6 | E23: LS/+12V | F23: PinHeader_1x03_P2.54mm_Vertical | G23: Wurth Elektronik | H23: 61300311121 | I23: Kolikova lista 1x3 2,54 mm | J23: Konektor/ostatní | K23: ANO | M23: =IF(L23="","",D23*L23)
A24: 17 | B24: J1 | C24: 1 | D24: =IF(K24="NE",0,IF(J24="Pasivní",ROUNDUP(C24*$C$3*(1+$C$4),0)+$C$5,C24*$C$3)) -> 2 | E24: HCCPHPE24BKA90F | F24: Aptiv_SICMA_HCCPHPE24BKA90F_24P_RA | G24: Amphenol FCI | H24: HCCPHPE24BKA90F | I24: SICMA hybrid 24 pin, uhlovy, do DPS | J24: Konektor/ostatní | K24: ANO | M24: =IF(L24="","",D24*L24) | N24: Protikus (zásuvka + kontakty) viz list Mechanika
A25: 18 | B25: C24, C33, C37, C41, C45, C49, C53, C57, C61 | C25: 9 | D25: =IF(K25="NE",0,IF(J25="Pasivní",ROUNDUP(C25*$C$3*(1+$C$4),0)+$C$5,C25*$C$3)) -> 25 | E25: 10u / 10u/16V | F25: C_0805 | G25: Samsung | H25: CL21A106KOQNNNE | I25: MLCC 10uF 16V X5R 0805 | J25: Pasivní | K25: ANO | M25: =IF(L25="","",D25*L25)
A26: 19 | B26: C13, C14, C15, C16, C17, C22, C32, C36, C40, C44, C48, C52, C56, C60 | C26: 14 | D26: =IF(K26="NE",0,IF(J26="Pasivní",ROUNDUP(C26*$C$3*(1+$C$4),0)+$C$5,C26*$C$3)) -> 36 | E26: 10n / 10n/50V | F26: C_0805 | G26: Samsung | H26: CL21B103KBANNNC | I26: MLCC 10nF 50V X7R 0805 | J26: Pasivní | K26: ANO | M26: =IF(L26="","",D26*L26)
A27: 20 | B27: C3, C5, C18, C19, C20, C21, C25, C26, C27, C28, C29, C31, C35, C39, C43, C47, C51, C55, C59 | C27: 19 | D27: =IF(K27="NE",0,IF(J27="Pasivní",ROUNDUP(C27*$C$3*(1+$C$4),0)+$C$5,C27*$C$3)) -> 47 | E27: 100n / 100n/50V | F27: C_0805 | G27: Samsung | H27: CL21B104KBCNNNC | I27: MLCC 100nF 50V X7R 0805 | J27: Pasivní | K27: ANO | M27: =IF(L27="","",D27*L27)
A28: 21 | B28: C62 | C28: 1 | D28: =IF(K28="NE",0,IF(J28="Pasivní",ROUNDUP(C28*$C$3*(1+$C$4),0)+$C$5,C28*$C$3)) -> 8 | E28: 1u/50V | F28: C_0805 | G28: Samsung | H28: CL21B105KBFNNNE | I28: MLCC 1uF 50V X7R 0805 | J28: Pasivní | K28: ANO | M28: =IF(L28="","",D28*L28)
A29: 22 | B29: C23 | C29: 1 | D29: =IF(K29="NE",0,IF(J29="Pasivní",ROUNDUP(C29*$C$3*(1+$C$4),0)+$C$5,C29*$C$3)) -> 8 | E29: 330n | F29: C_0805 | G29: Samsung | H29: CL21B334KBFNNNE | I29: MLCC 330nF 50V X7R 0805 | J29: Pasivní | K29: ANO | M29: =IF(L29="","",D29*L29)
A30: 23 | B30: C1, C2 | C30: 2 | D30: =IF(K30="NE",0,IF(J30="Pasivní",ROUNDUP(C30*$C$3*(1+$C$4),0)+$C$5,C30*$C$3)) -> 10 | E30: 47u/50V | F30: CP_Elec_8x10 | G30: Panasonic | H30: EEE-FK1H470P | I30: Elektrolyt 47uF 50V 8x10,2 mm 105 C | J30: Pasivní | K30: ANO | M30: =IF(L30="","",D30*L30) | N30: C2 změněn z 22u na 47u/50V (stejné pouzdro jako C1)
A31: 24 | B31: C8 | C31: 1 | D31: =IF(K31="NE",0,IF(J31="Pasivní",ROUNDUP(C31*$C$3*(1+$C$4),0)+$C$5,C31*$C$3)) -> 8 | E31: 220n/100V | F31: C_0805 | G31: Murata | H31: GCM21BR72A224KA37L | I31: MLCC 220nF 100V X7R 0805, AEC-Q200 | J31: Pasivní | K31: ANO | M31: =IF(L31="","",D31*L31)
A32: 25 | B32: R18, R19, R20, R21, R31 | C32: 5 | D32: =IF(K32="NE",0,IF(J32="Pasivní",ROUNDUP(C32*$C$3*(1+$C$4),0)+$C$5,C32*$C$3)) -> 16 | E32: 100k / 100k 1% | F32: R_0805 | G32: Yageo | H32: RC0805FR-07100KL | I32: Rezistor 100k 1% 0805 | J32: Pasivní | K32: ANO | M32: =IF(L32="","",D32*L32)
A33: 26 | B33: R3, R5, R7, R9, R11, R14, R16, R25, R26, R27, R28, R29, R36, R39, R44, R47, R52, R55, R60, R63, R68, R71, R76, R79, R84, R87, R92, R95 | C33: 28 | D33: =IF(K33="NE",0,IF(J33="Pasivní",ROUNDUP(C33*$C$3*(1+$C$4),0)+$C$5,C33*$C$3)) -> 67 | E33: 10k / 10k 1% | F33: R_0805 | G33: Yageo | H33: RC0805FR-0710KL | I33: Rezistor 10k 1% 0805 | J33: Pasivní | K33: ANO | M33: =IF(L33="","",D33*L33)
A34: 27 | B34: R35, R38, R43, R46, R51, R54, R59, R62, R67, R70, R75, R78, R83, R86, R91, R94, R97 | C34: 17 | D34: =IF(K34="NE",0,IF(J34="Pasivní",ROUNDUP(C34*$C$3*(1+$C$4),0)+$C$5,C34*$C$3)) -> 43 | E34: 1k / 1k 1% | F34: R_0805 | G34: Yageo | H34: RC0805FR-071KL | I34: Rezistor 1k 1% 0805 | J34: Pasivní | K34: ANO | M34: =IF(L34="","",D34*L34)
A35: 28 | B35: R22 | C35: 1 | D35: =IF(K35="NE",0,IF(J35="Pasivní",ROUNDUP(C35*$C$3*(1+$C$4),0)+$C$5,C35*$C$3)) -> 8 | E35: 1M | F35: R_0805 | G35: Yageo | H35: RC0805FR-071ML | I35: Rezistor 1M 1% 0805 | J35: Pasivní | K35: ANO | M35: =IF(L35="","",D35*L35)
A36: 29 | B36: R23 | C36: 1 | D36: =IF(K36="NE",0,IF(J36="Pasivní",ROUNDUP(C36*$C$3*(1+$C$4),0)+$C$5,C36*$C$3)) -> 8 | E36: 22k | F36: R_0805 | G36: Yageo | H36: RC0805FR-0722KL | I36: Rezistor 22k 1% 0805 | J36: Pasivní | K36: ANO | M36: =IF(L36="","",D36*L36)
A37: 30 | B37: R24 | C37: 1 | D37: =IF(K37="NE",0,IF(J37="Pasivní",ROUNDUP(C37*$C$3*(1+$C$4),0)+$C$5,C37*$C$3)) -> 8 | E37: 300k | F37: R_0805 | G37: Yageo | H37: RC0805FR-07300KL | I37: Rezistor 300k 1% 0805 | J37: Pasivní | K37: ANO | M37: =IF(L37="","",D37*L37)
A38: 31 | B38: R13 | C38: 1 | D38: =IF(K38="NE",0,IF(J38="Pasivní",ROUNDUP(C38*$C$3*(1+$C$4),0)+$C$5,C38*$C$3)) -> 8 | E38: 35k7 1% | F38: R_0805 | G38: Yageo | H38: RC0805FR-0735K7L | I38: Rezistor 35k7 1% 0805 | J38: Pasivní | K38: ANO | M38: =IF(L38="","",D38*L38)
A39: 32 | B39: R37, R45, R53, R61, R69, R77, R85, R93 | C39: 8 | D39: =IF(K39="NE",0,IF(J39="Pasivní",ROUNDUP(C39*$C$3*(1+$C$4),0)+$C$5,C39*$C$3)) -> 23 | E39: 3k9 | F39: R_0805 | G39: Yageo | H39: RC0805FR-073K9L | I39: Rezistor 3k9 1% 0805 | J39: Pasivní | K39: ANO | M39: =IF(L39="","",D39*L39)
A40: 33 | B40: R4, R6, R8, R10, R12 | C40: 5 | D40: =IF(K40="NE",0,IF(J40="Pasivní",ROUNDUP(C40*$C$3*(1+$C$4),0)+$C$5,C40*$C$3)) -> 16 | E40: 47k | F40: R_0805 | G40: Yageo | H40: RC0805FR-0747KL | I40: Rezistor 47k 1% 0805 | J40: Pasivní | K40: ANO | M40: =IF(L40="","",D40*L40)
A41: 34 | B41: R34, R42, R50, R58, R66, R74, R82, R90 | C41: 8 | D41: =IF(K41="NE",0,IF(J41="Pasivní",ROUNDUP(C41*$C$3*(1+$C$4),0)+$C$5,C41*$C$3)) -> 23 | E41: 47R | F41: R_0805 | G41: Yageo | H41: RC0805FR-0747RL | I41: Rezistor 47R 1% 0805 | J41: Pasivní | K41: ANO | M41: =IF(L41="","",D41*L41)
...

Sheet DPS výroba
A1: Deska plošných spojů – parametry pro výrobce
A3: Soubory | B3: fab/PDM_gerber.zip (Gerber X2 + vrtání Excellon), fab/PDM-pos.csv (pozice pro osazení)
A4: Rozměr | B4: 124 × 116 mm
A5: Počet vrstev | B5: 4 (F.Cu, In1 = GND, In2 = VBAT, B.Cu)
A6: Tloušťka desky | B6: 1,6 mm
A7: Měď vnější vrstvy | B7: 2 oz (70 µm) – nutné kvůli kanálům 25 A
A8: Měď vnitřní vrstvy | B8: 2 oz doporučeno (VBAT rovina vede proud všech kanálů), minimum 1 oz
A9: Min. šířka spoje / mezera | B9: 0,15 mm / 0,2 mm
A10: Prokovy | B10: 0,3 mm vrták / 0,6 mm ploška
A11: Povrch | B11: ENIG (rovné plošky pro TSDSO-14 a SOT-223), případně HASL bezolovnatý
A12: Maska / potisk | B12: zelená / bílý
A13: Počet kusů | B13: =Objednávka!C3 -> 2
A14: Poznámka | B14: Tepelné prokovy pod BTS7002 (ploška VBAT): při osazování hlídat, aby pájka nestekla do prokovů (tenting / zaplnění prokovů).

Sheet Mechanika
A1: Mechanika a příslušenství (není ve schématu)
A3: Položka | B3: Ks / deska | C3: Ks objednat | D3: Specifikace | E3: Poznámka
A4: Propojka (jumper) 2,54 mm | B4: 3 | C4: =B4*Objednávka!$C$3 -> 6 | D4: Würth 60900213421 nebo ekvivalent | E4: JP1–JP3: 1-2 = vstup spínaný k zemi (LS), 2-3 = aktivní +12 V
A5: Šroub M6 pro VBAT (J2) | B5: 1 | C5: =B5*Objednávka!$C$3 -> 2 | D5: M6 × 20 + 2× podložka M6 + pružná podložka + matice M6 | E5: Kabelové oko VBAT pod hlavu šroubu; ploška J2 je VBAT
A6: Kabelové oko M6 | B6: 1 | C6: =B6*Objednávka!$C$3 -> 2 | D6: Lisovací oko M6 pro průřez VBAT kabelu (např. 16–25 mm²) | E6: Průřez podle celkového proudu
A7: Hlavní pojistka VBAT | B7: 1 | C7: =B7*Objednávka!$C$3 -> 2 | D7: MIDI/ANL pojistka + držák, hodnota podle průřezu VBAT kabelu | E7: Co nejblíž baterii; PDM nemá vlastní hlavní pojistku
A8: Protikus konektoru J1 | B8: 1 | C8: =B8*Objednávka!$C$3 -> 2 | D8: SICMA 24-pin zásuvka k HCCPHPE24BKA90F + kontakty 1,5 mm (18×) a 2,8 mm (6×) + záslepky/těsnění | E8: Přesné objednací číslo protikusu dohledat v katalogu Amphenol FCI / Aptiv (neověřeno)
A9: Montážní šrouby M3 | B9: 4 | C9: =B9*Objednávka!$C$3 -> 8 | D9: Šroub M3 + distanční sloupek podle krabičky | E9: Otvory H1–H4 v rozích desky
